Workbook
Name ActivityNames: hiddenData!$A$1:$A$13
Name Bottleneck0: #REF!
Name Bottleneck1: #REF!
Name Consumption0: hiddenData!$F$1:$F$2
Name Consumption1: #REF!
Name Resources: hiddenData!$F$3:$F$4
Name TotalCosts0: hiddenData!$B$1:$B$13
Name TotalCosts1: #REF!
Name TotalTime0: hiddenData!$D$1:$D$13
Name TotalTime1: #REF!

Sheet Overview
A1: Report | B1: Simulation
A2: Date | B2: 1/24/26
A3: Time | B3: 11:48 PM
A4: User | B4: Iaguta Mihael
A5: Process | B5: 3. BPMN diagram
A7: Used scenario | B7: Duration in days | C7: Total cycle time | D7: Resource consumption | E7: Bottlenecks
A8: Test scenario | B8: 5 | C8: 0.13769676 | D8: 0.14032407

Sheet Costs
A1: Report | B1: Simulation
A2: Date | B2: 1/24/26
A3: Time | B3: 11:48 PM
A4: User | B4: Iaguta Mihael
A5: Process | B5: 3. BPMN diagram
A7: Execution costs of a process instance are the sum of fixed activity costs and resources costs. The latter ones are computed using defined responsibilities and activity execution durations. The following table shows selected process instance costs as well as the total sum of all costs:
A10: Used scenario | B10: Duration in days | C10: Average | D10: Minimum | E10: Maximum | F10: Total costs
A11: Test scenario | B11: 5 | C11: 2.37 | D11: 1.58 | E11: 3.68 | F11: 47.33
A13: The following table shows the costs caused by every activity of your process:
A15: Task | B15: Used scenario | C15: Duration in days | D15: Completed instances | E15: Average | F15: Minimum | G15: Maximum | H15: Total costs
A16: Prepare board | B16: Test scenario | C16: 5 | D16: 20 | E16: 1.88 | F16: 1.32 | G16: 2.5 | H16: 37.6
A17: Assign turn to player | B17: Test scenario | C17: 5 | D17: 25 | E17: 0.18 | F17: 0.13 | G17: 0.24 | H17: 4.56
A18: Roll dice | B18: Test scenario | C18: 5 | D18: 32 | E18: 0.01 | F18: 0.01 | G18: 0.01 | H18: 0.22
A19: Do nothing | B19: Test scenario | C19: 5 | D19: 11 | E19: 0.01 | F19: 0.01 | G19: 0.01 | H19: 0.08
A20: Land on property | B20: Test scenario | C20: 5 | D20: 16 | E20: 0.01 | F20: 0.01 | G20: 0.01 | H20: 0.11
A21: Pay the player | B21: Test scenario | C21: 5 | D21: 6 | E21: 0.06 | F21: 0.05 | G21: 0.07 | H21: 0.35
A22: Check the property | B22: Test scenario | C22: 5 | D22: 10 | E22: 0.24 | F22: 0.06 | G22: 0.38 | H22: 2.42
A23: Send the payment | B23: Test scenario | C23: 5 | D23: 5 | E23: 0.09 | F23: 0.07 | G23: 0.1 | H23: 0.43
A24: Offer the property to the player | B24: Test scenario | C24: 5 | D24: 5 | E24: 0.2 | F24: 0.15 | G24: 0.24 | H24: 0.98
A25: End turn | B25: Test scenario | C25: 5 | D25: 27 | E25: 0.01 | F25: 0.01 | G25: 0.01 | H25: 0.38
A26: Go to Jail | B26: Test scenario | C26: 5 | D26: 5 | E26: 0.01 | F26: 0.01 | G26: 0.01 | H26: 0.03
A27: Put player in Jail | B27: Test scenario | C27: 5 | D27: 5 | E27: 0.02 | F27: 0.02 | G27: 0.02 | H27: 0.1
A28: Release Player | B28: Test scenario | C28: 5 | D28: 3 | E28: 0.02 | F28: 0.02 | G28: 0.02 | H28: 0.06
A30: Legend
A31: All values are relative to the highest value
A32: Latest run | B32: Previous run
A33: 100% | B33: 100%
A34: >87.5% | B34: >87.5%
A35: >75% | B35: >75%
A36: >62.5% | B36: >62.5%
A37: >50% | B37: >50%
A38: <=50% or smallest value | B38: <=50% or smallest value

Sheet Total cost chart
A1: Report | B1: Simulation
A2: Date | B2: 1/24/26
A3: Time | B3: 11:48 PM
A4: User | B4: Iaguta Mihael
A5: Process | B5: 3. BPMN diagram

Sheet Total cycle time
A1: Report | B1: Simulation
A2: Date | B2: 1/24/26
A3: Time | B3: 11:48 PM
A4: User | B4: Iaguta Mihael
A5: Process | B5: 3. BPMN diagram
A8: The cycle time of a process instance is measured between its start and completion. The following table shows selected process instance cycle times as well as the total sum of all run cycles:
A10: Used scenario | B10: Duration in days | C10: Average | D10: Minimum | E10: Maximum | F10: Total cycle time
A11: Test scenario | B11: 5 | C11: 0.006875 | D11: 0.004537037 | E11: 0.011365741 | F11: 0.13769676
A14: Execution times incl. waiting times
A15: The following table shows for each activity how long its execution took with respect to existing working schedules without taking available resources into account:
A17: Task | B17: Used scenario | C17: Duration in days | D17: Completed instances | E17: Average | F17: Minimum | G17: Maximum | H17: Total execution time
A18: Prepare board | B18: Test scenario | C18: 5 | D18: 20 | E18: 0.0052199074 | F18: 0.0036574074 | G18: 0.0069444444 | H18: 0.10444444
A19: Assign turn to player | B19: Test scenario | C19: 5 | D19: 25 | E19: 0.00049768519 | F19: 0.00034722222 | G19: 0.0006712963 | H19: 0.012662037
A20: Roll dice | B20: Test scenario | C20: 5 | D20: 32 | E20: 5.787037e-05 | F20: 5.787037e-05 | G20: 5.787037e-05 | H20: 0.0018518519
A21: Do nothing | B21: Test scenario | C21: 5 | D21: 11 | E21: 5.787037e-05 | F21: 5.787037e-05 | G21: 5.787037e-05 | H21: 0.00063657407
A22: Land on property | B22: Test scenario | C22: 5 | D22: 16 | E22: 5.787037e-05 | F22: 5.787037e-05 | G22: 5.787037e-05 | H22: 0.00092592593
A23: Pay the player | B23: Test scenario | C23: 5 | D23: 6 | E23: 0.00048611111 | F23: 0.00038194444 | G23: 0.00059027778 | H23: 0.0029166667
A24: Check the property | B24: Test scenario | C24: 5 | D24: 10 | E24: 0.0006712963 | F24: 0.00016203704 | G24: 0.0010532407 | H24: 0.0067361111
A25: Send the payment | B25: Test scenario | C25: 5 | D25: 5 | E25: 0.00070601852 | F25: 0.00056712963 | G25: 0.00085648148 | H25: 0.0035532407
A26: Offer the property to the player | B26: Test scenario | C26: 5 | D26: 5 | E26: 0.00054398148 | F26: 0.00041666667 | G26: 0.00065972222 | H26: 0.0027199074
A27: End turn | B27: Test scenario | C27: 5 | D27: 27 | E27: 0.00011574074 | F27: 0.00011574074 | G27: 0.00011574074 | H27: 0.003125
A28: Go to Jail | B28: Test scenario | C28: 5 | D28: 5 | E28: 5.787037e-05 | F28: 5.787037e-05 | G28: 5.787037e-05 | H28: 0.00028935185
A29: Put player in Jail | B29: Test scenario | C29: 5 | D29: 5 | E29: 5.787037e-05 | F29: 5.787037e-05 | G29: 5.787037e-05 | H29: 0.00028935185
A30: Release Player | B30: Test scenario | C30: 5 | D30: 3 | E30: 5.787037e-05 | F30: 5.787037e-05 | G30: 5.787037e-05 | H30: 0.00017361111
A33: Pure execution times
A34: Within a process instance, several activities are executed. This happens sub-sequentially, delayed or in parallel. The following table shows for each activity how long its pure execution took. The values ​​do not include any existing waiting times, those are included in the table at 'Execution times incl. waiting times'. Please note that waiting times due to missing resources are not displayed here, as they are analyzed under “Bottlenecks”.
A36: Task | B36: Used scenario | C36: Duration in days | D36: Completed instances | E36: Average | F36: Minimum | G36: Maximum | H36: Total execution time
A37: Prepare board | B37: Test scenario | C37: 5 | D37: 20 | E37: 0.0052222222 | F37: 0.0036574074 | G37: 0.0069444444 | H37: 0.10444444
A38: Assign turn to player | B38: Test scenario | C38: 5 | D38: 25 | E38: 0.00050648148 | F38: 0.00034722222 | G38: 0.0006712963 | H38: 0.012662037
A39: Roll dice | B39: Test scenario | C39: 5 | D39: 32 | E39: 5.787037e-05 | F39: 5.787037e-05 | G39: 5.787037e-05 | H39: 0.0018518519
A40: Do nothing | B40: Test scenario | C40: 5 | D40: 11 | E40: 5.787037e-05 | F40: 5.787037e-05 | G40: 5.787037e-05 | H40: 0.00063657407
A41: Land on property | B41: Test scenario | C41: 5 | D41: 16 | E41: 5.787037e-05 | F41: 5.787037e-05 | G41: 5.787037e-05 | H41: 0.00092592593
A42: Pay the player | B42: Test scenario | C42: 5 | D42: 6 | E42: 0.00048611111 | F42: 0.00038194444 | G42: 0.00059027778 | H42: 0.0029166667
A43: Check the property | B43: Test scenario | C43: 5 | D43: 10 | E43: 0.00067361111 | F43: 0.00016203704 | G43: 0.0010532407 | H43: 0.0067361111
A44: Send the payment | B44: Test scenario | C44: 5 | D44: 5 | E44: 0.00071064815 | F44: 0.00056712963 | G44: 0.00085648148 | H44: 0.0035532407
A45: Offer the property to the player | B45: Test scenario | C45: 5 | D45: 5 | E45: 0.00054398148 | F45: 0.00041666667 | G45: 0.00065972222 | H45: 0.0027199074
A46: End turn | B46: Test scenario | C46: 5 | D46: 27 | E46: 0.00011574074 | F46: 0.00011574074 | G46: 0.00011574074 | H46: 0.003125
A47: Go to Jail | B47: Test scenario | C47: 5 | D47: 5 | E47: 5.787037e-05 | F47: 5.787037e-05 | G47: 5.787037e-05 | H47: 0.00028935185
A48: Put player in Jail | B48: Test scenario | C48: 5 | D48: 5 | E48: 5.787037e-05 | F48: 5.787037e-05 | G48: 5.787037e-05 | H48: 0.00028935185
A49: Release Player | B49: Test scenario | C49: 5 | D49: 3 | E49: 5.787037e-05 | F49: 5.787037e-05 | G49: 5.787037e-05 | H49: 0.00017361111
...

Sheet Total time chart
A1: Report | B1: Simulation
A2: Date | B2: 1/24/26
A3: Time | B3: 11:48 PM
A4: User | B4: Iaguta Mihael
A5: Process | B5: 3. BPMN diagram

Sheet Resource consumption
A1: Report | B1: Simulation
A2: Date | B2: 1/24/26
A3: Time | B3: 11:48 PM
A4: User | B4: Iaguta Mihael
A5: Process | B5: 3. BPMN diagram
A7: The execution of activities is performed by resources. The following table shows the workload of all resources in your scenario:
A10: Resources | B10: Used scenario | C10: Duration in days | D10: Consumed time | E10: Workload
A11: Bank | B11: Test scenario | C11: 5 | D11: 0.12702546 | E11: 0.0799
A12: Player | B12: Test scenario | C12: 5 | D12: 0.013298611 | E12: 0.0084
A14: Legend
A15: All values are relative to the highest value
A16: Latest run | B16: Previous run
A17: 100% | B17: 100%
A18: >87.5% | B18: >87.5%
A19: >75% | B19: >75%
A20: >62.5% | B20: >62.5%
A21: >50% | B21: >50%
A22: <=50% or smallest value | B22: <=50% or smallest value

Sheet Resource consumption chart
A1: Report | B1: Simulation
A2: Date | B2: 1/24/26
A3: Time | B3: 11:48 PM
A4: User | B4: Iaguta Mihael
A5: Process | B5: 3. BPMN diagram

Sheet hiddenData
A1: =Costs!A16 | B1: =Costs!H16 | D1: ='Total cycle time'!H37 | F1: ='Resource consumption'!D11 | J1: Latest run Total costs
A2: =Costs!A17 | B2: =Costs!H17 | D2: ='Total cycle time'!H38 | F2: ='Resource consumption'!D12 | J2: Latest run Total cycle time
A3: =Costs!A18 | B3: =Costs!H18 | D3: ='Total cycle time'!H39 | F3: ='Resource consumption'!A11 | J3: Latest run Workload
A4: =Costs!A19 | B4: =Costs!H19 | D4: ='Total cycle time'!H40 | F4: ='Resource consumption'!A12
A5: =Costs!A20 | B5: =Costs!H20 | D5: ='Total cycle time'!H41
A6: =Costs!A21 | B6: =Costs!H21 | D6: ='Total cycle time'!H42
A7: =Costs!A22 | B7: =Costs!H22 | D7: ='Total cycle time'!H43
A8: =Costs!A23 | B8: =Costs!H23 | D8: ='Total cycle time'!H44
A9: =Costs!A24 | B9: =Costs!H24 | D9: ='Total cycle time'!H45
A10: =Costs!A25 | B10: =Costs!H25 | D10: ='Total cycle time'!H46
A11: =Costs!A26 | B11: =Costs!H26 | D11: ='Total cycle time'!H47
A12: =Costs!A27 | B12: =Costs!H27 | D12: ='Total cycle time'!H48
A13: =Costs!A28 | B13: =Costs!H28 | D13: ='Total cycle time'!H49

Sheet Scenario Test scenario
A1: Report | B1: Simulation
A2: Date | B2: 1/24/26
A3: Time | B3: 11:48 PM
A4: User | B4: Iaguta Mihael
A5: Process | B5: 3. BPMN diagram
A7: Costs and Duration
A9: Task | B9: Execution costs | C9: Execution time
A10: Prepare board | B10: 0 | C10: 00h 05m - 00h 10m
A11: Assign turn to player | B11: 0 | C11: 00h 00m 30s - 00h 01m
A12: Roll dice | B12: 0 | C12: 00h 00m 05s
A13: Do nothing | B13: 0 | C13: 00h 00m 05s
A14: Land on property | B14: 0 | C14: 00h 00m 05s
A15: Pay the player | B15: 0 | C15: 00h 00m 30s - 00h 01m
A16: Check the property | B16: 0 | C16: Average 00h 01m, deviation 00h 00m 15s
A17: Send the payment | B17: 0 | C17: Average 00h 01m, deviation 00h 00m 15s
A18: Offer the property to the player | B18: 0 | C18: 00h 00m 30s - 00h 01m
A19: End turn | B19: 0 | C19: 00h 00m 10s
A20: Go to Jail | B20: 0 | C20: 00h 00m 05s
A21: Put player in Jail | B21: 0 | C21: 00h 00m 05s
A22: Release Player | B22: 0 | C22: 00h 00m 05s
A25: Frequency and probabilities
A27: Start event | B27: Frequency
A28: Start game | B28: On Mon-Fri; overall 20 times
A30: Gateway | B30: Decision | C30: Probability
A31: Choice? | B31: 1 | C31: 0.4
B32: 2 | C32: 0.4
B33: 3 | C33: 0.2
A34: Property owned? | B34: No | C34: 0.5
B35: Yes | C35: 0.5
A36: Wants to buy? | B36: No | C36: 0.5
B37: Yes | C37: 0.5
A38: Game done? | B38: No | C38: 0.25
B39: Yes | C39: 0.75
A40: Did player escape? | B40: No | C40: 0.5
B41: Yes | C41: 0.5
A44: Resources
A46: Role | B46: Work schedules | C46: Costs/hour
A47: Bank | B47: 1 employees; 40 hours per week | C47: 15
A48: Player | B48: 1 employees; 40 hours per week | C48: 5
